{"name": "Credentials", "status": "broken", "statusDetails": {"message": "urllib3.exceptions.ProtocolError: ('Connection aborted.', ConnectionResetError(10054, 'Istniejące połączenie zostało gwałtownie zamknięte przez zdalnego hosta', None, 10054, None))\n", "trace": "  File \"C:\\Users\\3last\\AppData\\Local\\Packages\\PythonSoftwareFoundation.Python.3.11_qbz5n2kfra8p0\\LocalCache\\local-packages\\Python311\\site-packages\\behave\\model.py\", line 1329, in run\n    match.run(runner.context)\n  File \"C:\\Users\\3last\\AppData\\Local\\Packages\\PythonSoftwareFoundation.Python.3.11_qbz5n2kfra8p0\\LocalCache\\local-packages\\Python311\\site-packages\\behave\\matchers.py\", line 98, in run\n    self.func(context, *args, **kwargs)\n  File \"steps\\steps.py\", line 50, in step_impl\n    assert credentials.credentials_exists()\n           ^^^^^^^^^^^^^^^^^^^^^^^^^^^^^^^^\n  File \"D:\\Programowanie\\Github\\Calculator\\Tests\\automation.py\", line 108, in credentials_exists\n    return PositionValidator.check_if_exists(self.driver, CredentialsLocators.send)\n           ^^^^^^^^^^^^^^^^^^^^^^^^^^^^^^^^^^^^^^^^^^^^^^^^^^^^^^^^^^^^^^^^^^^^^^^^\n  File \"D:\\Programowanie\\Github\\Calculator\\Tests\\automation.py\", line 44, in check_if_exists\n    info = driver.find_element(*check).is_displayed()\n           ^^^^^^^^^^^^^^^^^^^^^^^^^^^\n  File \"C:\\Users\\3last\\AppData\\Local\\Packages\\PythonSoftwareFoundation.Python.3.11_qbz5n2kfra8p0\\LocalCache\\local-packages\\Python311\\site-packages\\selenium\\webdriver\\remote\\webdriver.py\", line 976, in find_element\n    return self.execute(Command.FIND_ELEMENT, {\n           ^^^^^^^^^^^^^^^^^^^^^^^^^^^^^^^^^^^^\n  File \"C:\\Users\\3last\\AppData\\Local\\Packages\\PythonSoftwareFoundation.Python.3.11_qbz5n2kfra8p0\\LocalCache\\local-packages\\Python311\\site-packages\\selenium\\webdriver\\remote\\webdriver.py\", line 319, in execute\n    response = self.command_executor.execute(driver_command, params)\n               ^^^^^^^^^^^^^^^^^^^^^^^^^^^^^^^^^^^^^^^^^^^^^^^^^^^^^\n  File \"C:\\Users\\3last\\AppData\\Local\\Packages\\PythonSoftwareFoundation.Python.3.11_qbz5n2kfra8p0\\LocalCache\\local-packages\\Python311\\site-packages\\selenium\\webdriver\\remote\\remote_connection.py\", line 374, in execute\n    return self._request(command_info[0], url, body=data)\n           ^^^^^^^^^^^^^^^^^^^^^^^^^^^^^^^^^^^^^^^^^^^^^^\n  File \"C:\\Users\\3last\\AppData\\Local\\Packages\\PythonSoftwareFoundation.Python.3.11_qbz5n2kfra8p0\\LocalCache\\local-packages\\Python311\\site-packages\\selenium\\webdriver\\remote\\remote_connection.py\", line 402, in _request\n    resp = http.request(method, url, body=body, headers=headers)\n           ^^^^^^^^^^^^^^^^^^^^^^^^^^^^^^^^^^^^^^^^^^^^^^^^^^^^^\n  File \"C:\\Users\\3last\\AppData\\Local\\Packages\\PythonSoftwareFoundation.Python.3.11_qbz5n2kfra8p0\\LocalCache\\local-packages\\Python311\\site-packages\\urllib3\\request.py\", line 81, in request\n    return self.request_encode_body(\n           ^^^^^^^^^^^^^^^^^^^^^^^^^\n  File \"C:\\Users\\3last\\AppData\\Local\\Packages\\PythonSoftwareFoundation.Python.3.11_qbz5n2kfra8p0\\LocalCache\\local-packages\\Python311\\site-packages\\urllib3\\request.py\", line 173, in request_encode_body\n    return self.urlopen(method, url, **extra_kw)\n           ^^^^^^^^^^^^^^^^^^^^^^^^^^^^^^^^^^^^^\n  File \"C:\\Users\\3last\\AppData\\Local\\Packages\\PythonSoftwareFoundation.Python.3.11_qbz5n2kfra8p0\\LocalCache\\local-packages\\Python311\\site-packages\\urllib3\\poolmanager.py\", line 376, in urlopen\n    response = conn.urlopen(method, u.request_uri, **kw)\n               ^^^^^^^^^^^^^^^^^^^^^^^^^^^^^^^^^^^^^^^^^\n  File \"C:\\Users\\3last\\AppData\\Local\\Packages\\PythonSoftwareFoundation.Python.3.11_qbz5n2kfra8p0\\LocalCache\\local-packages\\Python311\\site-packages\\urllib3\\connectionpool.py\", line 799, in urlopen\n    retries = retries.increment(\n              ^^^^^^^^^^^^^^^^^^\n  File \"C:\\Users\\3last\\AppData\\Local\\Packages\\PythonSoftwareFoundation.Python.3.11_qbz5n2kfra8p0\\LocalCache\\local-packages\\Python311\\site-packages\\urllib3\\util\\retry.py\", line 550, in increment\n    raise six.reraise(type(error), error, _stacktrace)\n          ^^^^^^^^^^^^^^^^^^^^^^^^^^^^^^^^^^^^^^^^^^^^\n  File \"C:\\Users\\3last\\AppData\\Local\\Packages\\PythonSoftwareFoundation.Python.3.11_qbz5n2kfra8p0\\LocalCache\\local-packages\\Python311\\site-packages\\urllib3\\packages\\six.py\", line 769, in reraise\n    raise value.with_traceback(tb)\n  File \"C:\\Users\\3last\\AppData\\Local\\Packages\\PythonSoftwareFoundation.Python.3.11_qbz5n2kfra8p0\\LocalCache\\local-packages\\Python311\\site-packages\\urllib3\\connectionpool.py\", line 715, in urlopen\n    httplib_response = self._make_request(\n                       ^^^^^^^^^^^^^^^^^^^\n  File \"C:\\Users\\3last\\AppData\\Local\\Packages\\PythonSoftwareFoundation.Python.3.11_qbz5n2kfra8p0\\LocalCache\\local-packages\\Python311\\site-packages\\urllib3\\connectionpool.py\", line 467, in _make_request\n    six.raise_from(e, None)\n  File \"<string>\", line 3, in raise_from\n  File \"C:\\Users\\3last\\AppData\\Local\\Packages\\PythonSoftwareFoundation.Python.3.11_qbz5n2kfra8p0\\LocalCache\\local-packages\\Python311\\site-packages\\urllib3\\connectionpool.py\", line 462, in _make_request\n    httplib_response = conn.getresponse()\n                       ^^^^^^^^^^^^^^^^^^\n  File \"C:\\Program Files\\WindowsApps\\PythonSoftwareFoundation.Python.3.11_3.11.2544.0_x64__qbz5n2kfra8p0\\Lib\\http\\client.py\", line 1395, in getresponse\n    response.begin()\n  File \"C:\\Program Files\\WindowsApps\\PythonSoftwareFoundation.Python.3.11_3.11.2544.0_x64__qbz5n2kfra8p0\\Lib\\http\\client.py\", line 325, in begin\n    version, status, reason = self._read_status()\n                              ^^^^^^^^^^^^^^^^^^^\n  File \"C:\\Program Files\\WindowsApps\\PythonSoftwareFoundation.Python.3.11_3.11.2544.0_x64__qbz5n2kfra8p0\\Lib\\http\\client.py\", line 286, in _read_status\n    line = str(self.fp.readline(_MAXLINE + 1), \"iso-8859-1\")\n               ^^^^^^^^^^^^^^^^^^^^^^^^^^^^^^\n  File \"C:\\Program Files\\WindowsApps\\PythonSoftwareFoundation.Python.3.11_3.11.2544.0_x64__qbz5n2kfra8p0\\Lib\\socket.py\", line 706, in readinto\n    return self._sock.recv_into(b)\n           ^^^^^^^^^^^^^^^^^^^^^^^\n"}, "steps": [{"name": "Given I am situated on the credentials subpage", "status": "broken", "statusDetails": {"message": "urllib3.exceptions.ProtocolError: ('Connection aborted.', ConnectionResetError(10054, 'Istniejące połączenie zostało gwałtownie zamknięte przez zdalnego hosta', None, 10054, None))\n", "trace": "  File \"C:\\Users\\3last\\AppData\\Local\\Packages\\PythonSoftwareFoundation.Python.3.11_qbz5n2kfra8p0\\LocalCache\\local-packages\\Python311\\site-packages\\behave\\model.py\", line 1329, in run\n    match.run(runner.context)\n  File \"C:\\Users\\3last\\AppData\\Local\\Packages\\PythonSoftwareFoundation.Python.3.11_qbz5n2kfra8p0\\LocalCache\\local-packages\\Python311\\site-packages\\behave\\matchers.py\", line 98, in run\n    self.func(context, *args, **kwargs)\n  File \"steps\\steps.py\", line 50, in step_impl\n    assert credentials.credentials_exists()\n           ^^^^^^^^^^^^^^^^^^^^^^^^^^^^^^^^\n  File \"D:\\Programowanie\\Github\\Calculator\\Tests\\automation.py\", line 108, in credentials_exists\n    return PositionValidator.check_if_exists(self.driver, CredentialsLocators.send)\n           ^^^^^^^^^^^^^^^^^^^^^^^^^^^^^^^^^^^^^^^^^^^^^^^^^^^^^^^^^^^^^^^^^^^^^^^^\n  File \"D:\\Programowanie\\Github\\Calculator\\Tests\\automation.py\", line 44, in check_if_exists\n    info = driver.find_element(*check).is_displayed()\n           ^^^^^^^^^^^^^^^^^^^^^^^^^^^\n  File \"C:\\Users\\3last\\AppData\\Local\\Packages\\PythonSoftwareFoundation.Python.3.11_qbz5n2kfra8p0\\LocalCache\\local-packages\\Python311\\site-packages\\selenium\\webdriver\\remote\\webdriver.py\", line 976, in find_element\n    return self.execute(Command.FIND_ELEMENT, {\n           ^^^^^^^^^^^^^^^^^^^^^^^^^^^^^^^^^^^^\n  File \"C:\\Users\\3last\\AppData\\Local\\Packages\\PythonSoftwareFoundation.Python.3.11_qbz5n2kfra8p0\\LocalCache\\local-packages\\Python311\\site-packages\\selenium\\webdriver\\remote\\webdriver.py\", line 319, in execute\n    response = self.command_executor.execute(driver_command, params)\n               ^^^^^^^^^^^^^^^^^^^^^^^^^^^^^^^^^^^^^^^^^^^^^^^^^^^^^\n  File \"C:\\Users\\3last\\AppData\\Local\\Packages\\PythonSoftwareFoundation.Python.3.11_qbz5n2kfra8p0\\LocalCache\\local-packages\\Python311\\site-packages\\selenium\\webdriver\\remote\\remote_connection.py\", line 374, in execute\n    return self._request(command_info[0], url, body=data)\n           ^^^^^^^^^^^^^^^^^^^^^^^^^^^^^^^^^^^^^^^^^^^^^^\n  File \"C:\\Users\\3last\\AppData\\Local\\Packages\\PythonSoftwareFoundation.Python.3.11_qbz5n2kfra8p0\\LocalCache\\local-packages\\Python311\\site-packages\\selenium\\webdriver\\remote\\remote_connection.py\", line 402, in _request\n    resp = http.request(method, url, body=body, headers=headers)\n           ^^^^^^^^^^^^^^^^^^^^^^^^^^^^^^^^^^^^^^^^^^^^^^^^^^^^^\n  File \"C:\\Users\\3last\\AppData\\Local\\Packages\\PythonSoftwareFoundation.Python.3.11_qbz5n2kfra8p0\\LocalCache\\local-packages\\Python311\\site-packages\\urllib3\\request.py\", line 81, in request\n    return self.request_encode_body(\n           ^^^^^^^^^^^^^^^^^^^^^^^^^\n  File \"C:\\Users\\3last\\AppData\\Local\\Packages\\PythonSoftwareFoundation.Python.3.11_qbz5n2kfra8p0\\LocalCache\\local-packages\\Python311\\site-packages\\urllib3\\request.py\", line 173, in request_encode_body\n    return self.urlopen(method, url, **extra_kw)\n           ^^^^^^^^^^^^^^^^^^^^^^^^^^^^^^^^^^^^^\n  File \"C:\\Users\\3last\\AppData\\Local\\Packages\\PythonSoftwareFoundation.Python.3.11_qbz5n2kfra8p0\\LocalCache\\local-packages\\Python311\\site-packages\\urllib3\\poolmanager.py\", line 376, in urlopen\n    response = conn.urlopen(method, u.request_uri, **kw)\n               ^^^^^^^^^^^^^^^^^^^^^^^^^^^^^^^^^^^^^^^^^\n  File \"C:\\Users\\3last\\AppData\\Local\\Packages\\PythonSoftwareFoundation.Python.3.11_qbz5n2kfra8p0\\LocalCache\\local-packages\\Python311\\site-packages\\urllib3\\connectionpool.py\", line 799, in urlopen\n    retries = retries.increment(\n              ^^^^^^^^^^^^^^^^^^\n  File \"C:\\Users\\3last\\AppData\\Local\\Packages\\PythonSoftwareFoundation.Python.3.11_qbz5n2kfra8p0\\LocalCache\\local-packages\\Python311\\site-packages\\urllib3\\util\\retry.py\", line 550, in increment\n    raise six.reraise(type(error), error, _stacktrace)\n          ^^^^^^^^^^^^^^^^^^^^^^^^^^^^^^^^^^^^^^^^^^^^\n  File \"C:\\Users\\3last\\AppData\\Local\\Packages\\PythonSoftwareFoundation.Python.3.11_qbz5n2kfra8p0\\LocalCache\\local-packages\\Python311\\site-packages\\urllib3\\packages\\six.py\", line 769, in reraise\n    raise value.with_traceback(tb)\n  File \"C:\\Users\\3last\\AppData\\Local\\Packages\\PythonSoftwareFoundation.Python.3.11_qbz5n2kfra8p0\\LocalCache\\local-packages\\Python311\\site-packages\\urllib3\\connectionpool.py\", line 715, in urlopen\n    httplib_response = self._make_request(\n                       ^^^^^^^^^^^^^^^^^^^\n  File \"C:\\Users\\3last\\AppData\\Local\\Packages\\PythonSoftwareFoundation.Python.3.11_qbz5n2kfra8p0\\LocalCache\\local-packages\\Python311\\site-packages\\urllib3\\connectionpool.py\", line 467, in _make_request\n    six.raise_from(e, None)\n  File \"<string>\", line 3, in raise_from\n  File \"C:\\Users\\3last\\AppData\\Local\\Packages\\PythonSoftwareFoundation.Python.3.11_qbz5n2kfra8p0\\LocalCache\\local-packages\\Python311\\site-packages\\urllib3\\connectionpool.py\", line 462, in _make_request\n    httplib_response = conn.getresponse()\n                       ^^^^^^^^^^^^^^^^^^\n  File \"C:\\Program Files\\WindowsApps\\PythonSoftwareFoundation.Python.3.11_3.11.2544.0_x64__qbz5n2kfra8p0\\Lib\\http\\client.py\", line 1395, in getresponse\n    response.begin()\n  File \"C:\\Program Files\\WindowsApps\\PythonSoftwareFoundation.Python.3.11_3.11.2544.0_x64__qbz5n2kfra8p0\\Lib\\http\\client.py\", line 325, in begin\n    version, status, reason = self._read_status()\n                              ^^^^^^^^^^^^^^^^^^^\n  File \"C:\\Program Files\\WindowsApps\\PythonSoftwareFoundation.Python.3.11_3.11.2544.0_x64__qbz5n2kfra8p0\\Lib\\http\\client.py\", line 286, in _read_status\n    line = str(self.fp.readline(_MAXLINE + 1), \"iso-8859-1\")\n               ^^^^^^^^^^^^^^^^^^^^^^^^^^^^^^\n  File \"C:\\Program Files\\WindowsApps\\PythonSoftwareFoundation.Python.3.11_3.11.2544.0_x64__qbz5n2kfra8p0\\Lib\\socket.py\", line 706, in readinto\n    return self._sock.recv_into(b)\n           ^^^^^^^^^^^^^^^^^^^^^^^\n"}, "start": 1742232806124, "stop": 1742232811094}, {"name": "When I provide my credentials: John Smith, 3lastik@gmail.com, 123 123 123, Los Angeles and click send button", "status": "skipped", "start": 1742232811101, "stop": 1742232811101}, {"name": "Then I proceed to summary subpage and see Szczegóły dotyczące wybranych klimatyzatorów:", "status": "skipped", "start": 1742232811101, "stop": 1742232811101}], "start": 1742232806109, "stop": 1742232811101, "uuid": "35d0ba2e-76bc-4f3b-a95f-62605fc615b3", "historyId": "550a078485ac2a0b860a18ba3221a16d", "fullName": "Calculate_default: Credentials", "labels": [{"name": "severity", "value": "normal"}, {"name": "feature", "value": "Calculate_default"}, {"name": "framework", "value": "behave"}, {"name": "language", "value": "cpython3"}]}