{"name": "Calculate", "status": "broken", "statusDetails": {"message": "selenium.common.exceptions.ElementClickInterceptedException: Message: element click intercepted: Element is not clickable at point (967, 2350)\n  (Session info: MicrosoftEdge=134.0.3124.72)\n\n", "trace": "  File \"C:\\Users\\3last\\AppData\\Local\\Packages\\PythonSoftwareFoundation.Python.3.11_qbz5n2kfra8p0\\LocalCache\\local-packages\\Python311\\site-packages\\behave\\model.py\", line 1329, in run\n    match.run(runner.context)\n  File \"C:\\Users\\3last\\AppData\\Local\\Packages\\PythonSoftwareFoundation.Python.3.11_qbz5n2kfra8p0\\LocalCache\\local-packages\\Python311\\site-packages\\behave\\matchers.py\", line 98, in run\n    self.func(context, *args, **kwargs)\n  File \"steps\\steps.py\", line 29, in step_impl\n    context.driver.find_element(By.NAME, \"gree_device\").click()\n  File \"C:\\Users\\3last\\AppData\\Local\\Packages\\PythonSoftwareFoundation.Python.3.11_qbz5n2kfra8p0\\LocalCache\\local-packages\\Python311\\site-packages\\selenium\\webdriver\\remote\\webelement.py\", line 80, in click\n    self._execute(Command.CLICK_ELEMENT)\n  File \"C:\\Users\\3last\\AppData\\Local\\Packages\\PythonSoftwareFoundation.Python.3.11_qbz5n2kfra8p0\\LocalCache\\local-packages\\Python311\\site-packages\\selenium\\webdriver\\remote\\webelement.py\", line 633, in _execute\n    return self._parent.execute(command, params)\n           ^^^^^^^^^^^^^^^^^^^^^^^^^^^^^^^^^^^^^\n  File \"C:\\Users\\3last\\AppData\\Local\\Packages\\PythonSoftwareFoundation.Python.3.11_qbz5n2kfra8p0\\LocalCache\\local-packages\\Python311\\site-packages\\selenium\\webdriver\\remote\\webdriver.py\", line 321, in execute\n    self.error_handler.check_response(response)\n  File \"C:\\Users\\3last\\AppData\\Local\\Packages\\PythonSoftwareFoundation.Python.3.11_qbz5n2kfra8p0\\LocalCache\\local-packages\\Python311\\site-packages\\selenium\\webdriver\\remote\\errorhandler.py\", line 242, in check_response\n    raise exception_class(message, screen, stacktrace)\n"}, "steps": [{"name": "Given I am situated on the calculator subpage", "status": "passed", "start": 1742232585818, "stop": 1742232585839}, {"name": "When I click calculate button", "status": "broken", "statusDetails": {"message": "selenium.common.exceptions.ElementClickInterceptedException: Message: element click intercepted: Element is not clickable at point (967, 2350)\n  (Session info: MicrosoftEdge=134.0.3124.72)\n\n", "trace": "  File \"C:\\Users\\3last\\AppData\\Local\\Packages\\PythonSoftwareFoundation.Python.3.11_qbz5n2kfra8p0\\LocalCache\\local-packages\\Python311\\site-packages\\behave\\model.py\", line 1329, in run\n    match.run(runner.context)\n  File \"C:\\Users\\3last\\AppData\\Local\\Packages\\PythonSoftwareFoundation.Python.3.11_qbz5n2kfra8p0\\LocalCache\\local-packages\\Python311\\site-packages\\behave\\matchers.py\", line 98, in run\n    self.func(context, *args, **kwargs)\n  File \"steps\\steps.py\", line 29, in step_impl\n    context.driver.find_element(By.NAME, \"gree_device\").click()\n  File \"C:\\Users\\3last\\AppData\\Local\\Packages\\PythonSoftwareFoundation.Python.3.11_qbz5n2kfra8p0\\LocalCache\\local-packages\\Python311\\site-packages\\selenium\\webdriver\\remote\\webelement.py\", line 80, in click\n    self._execute(Command.CLICK_ELEMENT)\n  File \"C:\\Users\\3last\\AppData\\Local\\Packages\\PythonSoftwareFoundation.Python.3.11_qbz5n2kfra8p0\\LocalCache\\local-packages\\Python311\\site-packages\\selenium\\webdriver\\remote\\webelement.py\", line 633, in _execute\n    return self._parent.execute(command, params)\n           ^^^^^^^^^^^^^^^^^^^^^^^^^^^^^^^^^^^^^\n  File \"C:\\Users\\3last\\AppData\\Local\\Packages\\PythonSoftwareFoundation.Python.3.11_qbz5n2kfra8p0\\LocalCache\\local-packages\\Python311\\site-packages\\selenium\\webdriver\\remote\\webdriver.py\", line 321, in execute\n    self.error_handler.check_response(response)\n  File \"C:\\Users\\3last\\AppData\\Local\\Packages\\PythonSoftwareFoundation.Python.3.11_qbz5n2kfra8p0\\LocalCache\\local-packages\\Python311\\site-packages\\selenium\\webdriver\\remote\\errorhandler.py\", line 242, in check_response\n    raise exception_class(message, screen, stacktrace)\n"}, "start": 1742232585839, "stop": 1742232587201}, {"name": "Then I proceed to credentials subpage", "status": "skipped", "start": 1742232587202, "stop": 1742232587202}], "start": 1742232585817, "stop": 1742232587202, "uuid": "3bfe70b5-affa-4dbe-b98d-b0c8ed347ba9", "historyId": "ee488e1c37084f143b18d29742589363", "fullName": "Calculate_default: Calculate", "labels": [{"name": "severity", "value": "normal"}, {"name": "feature", "value": "Calculate_default"}, {"name": "framework", "value": "behave"}, {"name": "language", "value": "cpython3"}]}